Workbook
Name BaseTable: Lookups!$A$2:$B$9
Name HolidayDates: Lookups!$H$2:$H$8
Name SpecialDates: Lookups!$H$2:$H$10
Name ZoneTable: Lookups!$D$2:$F$266

Sheet README
B1: Uber / Ride-Sharing Operations Analytics — Excel workbook
B2: Uber pickups in New York City, Apr-Sep 2014 and Jan-Jun 2015 · prepared by Jatin Gohel
B4: Data source | C4: NYC Taxi & Limousine Commission data released under a FOIL request and published by FiveThirtyEight (github.com/fivethirtyeight/uber-tlc-foil-response).
B5: How it works | C5: The trip files (18.8 million rows) are too large for Excel, so the notebook aggregates them into tables (trips per date and hour, per base and day, per zone and month). Every number on the analysis sheets is a live formula on those tables.
B6: Formulas used | C6: SUMIFS, COUNTIFS, AVERAGEIFS, MINIFS, VLOOKUP, XLOOKUP (with IFERROR fallback), INDEX/MATCH, IF/IFS, CHOOSE, WEEKDAY, DATE, EDATE, YEAR, LARGE/SMALL, RANK.EQ, PERCENTILE.INC, CORREL.
B7: Not in the data | C7: Fares/revenue, trip distance and duration, drop-offs, cancellations, wait times and driver hours. Trips per active vehicle is a productivity proxy, not driver utilization.
B8: Excel version | C8: Needs Excel 2019, 2021 or Microsoft 365 (IFS, MINIFS). XLOOKUP cells fall back to INDEX/MATCH or VLOOKUP in Excel 2019.
B10: Sheet | C10: What it shows
B11: Summary | C11: KPI cards, trips by year and a ✓/✗ check of every KPI against the Python notebook.
B12: Monthly_Trend | C12: Trips, days and average trips per day by month; month-over-month and year-over-year growth.
B13: Time_Patterns | C13: Weekday × hour heat map, hour profile (weekday vs weekend), time bands, peak/quiet hours and weekdays.
B14: Daily_Calendar | C14: Top and bottom days, planning percentiles, holiday and blizzard effects vs a normal day, 7-day average chart.
B15: Geography | C15: Service areas (boroughs + airports), growth Jan→Jun, zone ranking, concentration, airport share by hour.
B16: Bases | C16: Share of trips by dispatching base, 2014 vs 2015.
... B23: Data_Dictionary | C23: Description of every data-table column.

Sheet Summary
B1: Uber / Ride-Sharing Operations Analytics — New York City, 2014–2015
B2: 18,804,806 Uber pickups (NYC TLC FOIL data) · every number below is a live formula on the data sheets
B4: Trips, Jan-Jun 2015 | E4: Average trips per day, 2015 | H4: Year-over-year growth | K4: Peak hour (2015)
B5: =SUMIFS(tblDaily[Trips],tblDaily[Period],"2015 Jan-Jun") -> 14270479 | E5: =AVERAGEIFS(tblDaily[Trips],tblDaily[Period],"2015 Jan-Jun") -> 78842.425 | H5: =Monthly_Trend!$E$25 -> 3.1436121 | K5: =Time_Patterns!$Q$16 -> 19
B6: Pickup records | E6: 181 days | H6: Apr-Jun 2015 vs Apr-Jun 2014 | K6: Highest average trips
B8: Manhattan share | E8: Airport share | H8: Trips per active vehicle / day | K8: Uber vs yellow taxis
B9: =Geography!$D$6 -> 0.7270684 | E9: =Geography!$D$9 -> 0.038936107 | H9: =Supply!$E$14 -> 8.9238212 | K9: =Market!$E$8 -> 0.077658492
B10: Of 2015 pickups (known zones) | E10: JFK + LaGuardia + Newark | H10: FOIL Jan-Feb 2015 (proxy) | K10: Trips per day, Sep 2014
B28: Trips by year | H28: Check: Excel formulas vs Python notebook
B29: Period | E29: Trips | F29: Avg / day | H29: KPI | K29: Excel | L29: Python | N29: Match
B30: 2014 Apr-Sep | E30: =SUMIFS(tblDaily[Trips],tblDaily[Period],B30) -> 4534327 | F30: =AVERAGEIFS(tblDaily[Trips],tblDaily[Period],B30) -> 24777.743 | H30: Trips 2015 | K30: =B5 -> 14270479 | L30: 14270479 | N30: =IF(ABS(K30-L30)<=0.5,"✓","✗") -> ✓
B31: 2015 Jan-Jun | E31: =SUMIFS(tblDaily[Trips],tblDaily[Period],B31) -> 14270479 | F31: =AVERAGEIFS(tblDaily[Trips],tblDaily[Period],B31) -> 78842.425 | H31: Avg trips per day 2015 | K31: =E5 -> 78842.425 | L31: 78842.425 | N31: =IF(ABS(K31-L31)<=0.01,"✓","✗") -> ✓
H32: YoY growth Apr-Jun | K32: =H5 -> 3.1436121 | L32: 3.1436121 | N32: =IF(ABS(K32-L32)<=5e-05,"✓","✗") -> ✓
H33: Peak hour 2015 | K33: =K5 -> 19 | L33: 19 | N33: =IF(ABS(K33-L33)<=0,"✓","✗") -> ✓
H34: Manhattan share | K34: =B9 -> 0.7270684 | L34: 0.727068 | N34: =IF(ABS(K34-L34)<=5e-05,"✓","✗") -> ✓
H35: Airport share | K35: =E9 -> 0.038936107 | L35: 0.038936 | N35: =IF(ABS(K35-L35)<=5e-05,"✓","✗") -> ✓
H36: Trips per vehicle-day | K36: =H9 -> 8.9238212 | L36: 8.923821 | N36: =IF(ABS(K36-L36)<=0.0005,"✓","✗") -> ✓
H37: Uber vs yellow, Sep 2014 | K37: =K9 -> 0.077658492 | L37: 0.077658 | N37: =IF(ABS(K37-L37)<=5e-05,"✓","✗") -> ✓
H39: Python = reports/kpi_summary.json (notebook). Excel = live formulas. ✓ = same value within rounding.

Sheet Monthly_Trend
A1: Monthly trend — trips, days and average trips per day
A2: Trips = SUMIFS over the Daily table between the 1st of the month and EDATE(month, 1). Month-over-month growth only within the same period.
A5: Month | B5: Period | C5: Trips | D5: Days | E5: Avg trips / day | F5: MoM growth | G5: MoM growth / day
A6: 41730 | B6: 2014 Apr-Sep | C6: =SUMIFS(tblDaily[Trips],tblDaily[Date],">="&A6,tblDaily[Date],"<"&EDATE(A6,1)) -> 564516 | D6: =COUNTIFS(tblDaily[Date],">="&A6,tblDaily[Date],"<"&EDATE(A6,1)) -> 30 | E6: =C6/D6 -> 18817.2
A7: 41760 | B7: 2014 Apr-Sep | C7: =SUMIFS(tblDaily[Trips],tblDaily[Date],">="&A7,tblDaily[Date],"<"&EDATE(A7,1)) -> 652435 | D7: =COUNTIFS(tblDaily[Date],">="&A7,tblDaily[Date],"<"&EDATE(A7,1)) -> 31 | E7: =C7/D7 -> 21046.29 | F7: =IF(B7=B6,C7/C6-1,"") -> 0.15574226 | G7: =IF(B7=B6,E7/E6-1,"") -> 0.11846026
A8: 41791 | B8: 2014 Apr-Sep | C8: =SUMIFS(tblDaily[Trips],tblDaily[Date],">="&A8,tblDaily[Date],"<"&EDATE(A8,1)) -> 663844 | D8: =COUNTIFS(tblDaily[Date],">="&A8,tblDaily[Date],"<"&EDATE(A8,1)) -> 30 | E8: =C8/D8 -> 22128.133 | F8: =IF(B8=B7,C8/C7-1,"") -> 0.017486799 | G8: =IF(B8=B7,E8/E7-1,"") -> 0.051403026
A9: 41821 | B9: 2014 Apr-Sep | C9: =SUMIFS(tblDaily[Trips],tblDaily[Date],">="&A9,tblDaily[Date],"<"&EDATE(A9,1)) -> 796121 | D9: =COUNTIFS(tblDaily[Date],">="&A9,tblDaily[Date],"<"&EDATE(A9,1)) -> 31 | E9: =C9/D9 -> 25681.323 | F9: =IF(B9=B8,C9/C8-1,"") -> 0.19925916 | G9: =IF(B9=B8,E9/E8-1,"") -> 0.16057338
A10: 41852 | B10: 2014 Apr-Sep | C10: =SUMIFS(tblDaily[Trips],tblDaily[Date],">="&A10,tblDaily[Date],"<"&EDATE(A10,1)) -> 829275 | D10: =COUNTIFS(tblDaily[Date],">="&A10,tblDaily[Date],"<"&EDATE(A10,1)) -> 31 | E10: =C10/D10 -> 26750.806 | F10: =IF(B10=B9,C10/C9-1,"") -> 0.041644423 | G10: =IF(B10=B9,E10/E9-1,"") -> 0.041644423
A11: 41883 | B11: 2014 Apr-Sep | C11: =SUMIFS(tblDaily[Trips],tblDaily[Date],">="&A11,tblDaily[Date],"<"&EDATE(A11,1)) -> 1028136 | D11: =COUNTIFS(tblDaily[Date],">="&A11,tblDaily[Date],"<"&EDATE(A11,1)) -> 30 | E11: =C11/D11 -> 34271.2 | F11: =IF(B11=B10,C11/C10-1,"") -> 0.23980103 | G11: =IF(B11=B10,E11/E10-1,"") -> 0.28112773
A12: 42005 | B12: 2015 Jan-Jun | C12: =SUMIFS(tblDaily[Trips],tblDaily[Date],">="&A12,tblDaily[Date],"<"&EDATE(A12,1)) -> 1953801 | D12: =COUNTIFS(tblDaily[Date],">="&A12,tblDaily[Date],"<"&EDATE(A12,1)) -> 31 | E12: =C12/D12 -> 63025.839 | F12: =IF(B12=B11,C12/C11-1,"") | G12: =IF(B12=B11,E12/E11-1,"")
A13: 42036 | B13: 2015 Jan-Jun | C13: =SUMIFS(tblDaily[Trips],tblDaily[Date],">="&A13,tblDaily[Date],"<"&EDATE(A13,1)) -> 2263620 | D13: =COUNTIFS(tblDaily[Date],">="&A13,tblDaily[Date],"<"&EDATE(A13,1)) -> 28 | E13: =C13/D13 -> 80843.571 | F13: =IF(B13=B12,C13/C12-1,"") -> 0.15857244 | G13: =IF(B13=B12,E13/E12-1,"") -> 0.28270521
A14: 42064 | B14: 2015 Jan-Jun | C14: =SUMIFS(tblDaily[Trips],tblDaily[Date],">="&A14,tblDaily[Date],"<"&EDATE(A14,1)) -> 2259773 | D14: =COUNTIFS(tblDaily[Date],">="&A14,tblDaily[Date],"<"&EDATE(A14,1)) -> 31 | E14: =C14/D14 -> 72895.903 | F14: =IF(B14=B13,C14/C13-1,"") -> -0.0016994902 | G14: =IF(B14=B13,E14/E13-1,"") -> -0.098309217
A15: 42095 | B15: 2015 Jan-Jun | C15: =SUMIFS(tblDaily[Trips],tblDaily[Date],">="&A15,tblDaily[Date],"<"&EDATE(A15,1)) -> 2280837 | D15: =COUNTIFS(tblDaily[Date],">="&A15,tblDaily[Date],"<"&EDATE(A15,1)) -> 30 | E15: =C15/D15 -> 76027.9 | F15: =IF(B15=B14,C15/C14-1,"") -> 0.0093212902 | G15: =IF(B15=B14,E15/E14-1,"") -> 0.042965333
A16: 42125 | B16: 2015 Jan-Jun | C16: =SUMIFS(tblDaily[Trips],tblDaily[Date],">="&A16,tblDaily[Date],"<"&EDATE(A16,1)) -> 2695553 | D16: =COUNTIFS(tblDaily[Date],">="&A16,tblDaily[Date],"<"&EDATE(A16,1)) -> 31 | E16: =C16/D16 -> 86953.323 | F16: =IF(B16=B15,C16/C15-1,"") -> 0.18182623 | G16: =IF(B16=B15,E16/E15-1,"") -> 0.14370281
A17: 42156 | B17: 2015 Jan-Jun | C17: =SUMIFS(tblDaily[Trips],tblDaily[Date],">="&A17,tblDaily[Date],"<"&EDATE(A17,1)) -> 2816895 | D17: =COUNTIFS(tblDaily[Date],">="&A17,tblDaily[Date],"<"&EDATE(A17,1)) -> 30 | E17: =C17/D17 -> 93896.5 | F17: =IF(B17=B16,C17/C16-1,"") -> 0.045015624 | G17: =IF(B17=B16,E17/E16-1,"") -> 0.079849478
A20: Year over year — same months (XLOOKUP with an INDEX/MATCH fallback for Excel 2019)
A21: Month | C21: Trips 2014 | D21: Trips 2015 | E21: Growth | F21: Multiple
A22: 42095 | C22: =INDEX($C$6:$C$17,MATCH(DATE(2014,MONTH(A22),1),$A$6:$A$17,0)) -> 564516 | D22: {=IFERROR(_xlfn.XLOOKUP(A22,$A$6:$A$17,$C$6:$C$17),INDEX($C$6:$C$17,MATCH(A22,$A$6:$A$17,0)))} -> 2280837 | E22: =D22/C22-1 -> 3.0403408 | F22: =D22/C22 -> 4.0403408
A23: 42125 | C23: =INDEX($C$6:$C$17,MATCH(DATE(2014,MONTH(A23),1),$A$6:$A$17,0)) -> 652435 | D23: {=IFERROR(_xlfn.XLOOKUP(A23,$A$6:$A$17,$C$6:$C$17),INDEX($C$6:$C$17,MATCH(A23,$A$6:$A$17,0)))} -> 2695553 | E23: =D23/C23-1 -> 3.1315273 | F23: =D23/C23 -> 4.1315273
A24: 42156 | C24: =INDEX($C$6:$C$17,MATCH(DATE(2014,MONTH(A24),1),$A$6:$A$17,0)) -> 663844 | D24: {=IFERROR(_xlfn.XLOOKUP(A24,$A$6:$A$17,$C$6:$C$17),INDEX($C$6:$C$17,MATCH(A24,$A$6:$A$17,0)))} -> 2816895 | E24: =D24/C24-1 -> 3.2433087 | F24: =D24/C24 -> 4.2433087
A25: Apr-Jun | C25: =SUM(C22:C24) -> 1880795 | D25: =SUM(D22:D24) -> 7793285 | E25: =D25/C25-1 -> 3.1436121 | F25: =D25/C25 -> 4.1436121

Sheet Time_Patterns
A1: Time patterns, Jan-Jun 2015 — average trips per hour by weekday and hour
A2: Each cell = AVERAGEIFS(Trips, Period, 2015, Weekday, row, Hour, column) over the Hourly table. Colour scale: white = low, blue = high.
A5: Weekday | B5: 0 | C5: 1 | D5: 2 | E5: 3 | F5: 4 | G5: 5 | H5: 6 | I5: 7 | J5: 8 | K5: 9 | L5: 10 | M5: 11 | N5: 12 | O5: 13 | P5: 14 | Q5: 15 | R5: 16 | S5: 17 | T5: 18 | U5: 19 | V5: 20 | W5: 21 | X5: 22 | Y5: 23
A6: Mon | B6: =AVERAGEIFS(tblHourly[Trips],tblHourly[Period],"2015 Jan-Jun",tblHourly[Weekday],$A6,tblHourly[Hour],B$5) -> 1925.3846 | C6: =AVERAGEIFS(tblHourly[Trips],tblHourly[Period],"2015 Jan-Jun",tblHourly[Weekday],$A6,tblHourly[Hour],C$5) -> 1082.2692 | D6: =AVERAGEIFS(tblHourly[Trips],tblHourly[Period],"2015 Jan-Jun",tblHourly[Weekday],$A6,tblHourly[Hour],D$5) -> 648.23077 | E6: =AVERAGEIFS(tblHourly[Trips],tblHourly[Period],"2015 Jan-Jun",tblHourly[Weekday],$A6,tblHourly[Hour],E$5) -> 488.38462 | F6: =AVERAGEIFS(tblHourly[Trips],tblHourly[Period],"2015 Jan-Jun",tblHourly[Weekday],$A6,tblHourly[Hour],F$5) -> 735.61538 | G6: =AVERAGEIFS(tblHourly[Trips],tblHourly[Period],"2015 Jan-Jun",tblHourly[Weekday],$A6,tblHourly[Hour],G$5) -> 1182.5769 | H6: =AVERAGEIFS(tblHourly[Trips],tblHourly[Period],"2015 Jan-Jun",tblHourly[Weekday],$A6,tblHourly[Hour],H$5) -> 1890.4231 | I6: =AVERAGEIFS(tblHourly[Trips],tblHourly[Period],"2015 Jan-Jun",tblHourly[Weekday],$A6,tblHourly[Hour],I$5) -> 2865.8846 | ... Y6: =AVERAGEIFS(tblHourly[Trips],tblHourly[Period],"2015 Jan-Jun",tblHourly[Weekday],$A6,tblHourly[Hour],Y$5) -> 2800.24
A7: Tue | B7: =AVERAGEIFS(tblHourly[Trips],tblHourly[Period],"2015 Jan-Jun",tblHourly[Weekday],$A7,tblHourly[Hour],B$5) -> 1785.24 | C7: =AVERAGEIFS(tblHourly[Trips],tblHourly[Period],"2015 Jan-Jun",tblHourly[Weekday],$A7,tblHourly[Hour],C$5) -> 991.48 | D7: =AVERAGEIFS(tblHourly[Trips],tblHourly[Period],"2015 Jan-Jun",tblHourly[Weekday],$A7,tblHourly[Hour],D$5) -> 581.44 | E7: =AVERAGEIFS(tblHourly[Trips],tblHourly[Period],"2015 Jan-Jun",tblHourly[Weekday],$A7,tblHourly[Hour],E$5) -> 396.4 | F7: =AVERAGEIFS(tblHourly[Trips],tblHourly[Period],"2015 Jan-Jun",tblHourly[Weekday],$A7,tblHourly[Hour],F$5) -> 586.16 | G7: =AVERAGEIFS(tblHourly[Trips],tblHourly[Period],"2015 Jan-Jun",tblHourly[Weekday],$A7,tblHourly[Hour],G$5) -> 1018.44 | H7: =AVERAGEIFS(tblHourly[Trips],tblHourly[Period],"2015 Jan-Jun",tblHourly[Weekday],$A7,tblHourly[Hour],H$5) -> 1843.48 | I7: =AVERAGEIFS(tblHourly[Trips],tblHourly[Period],"2015 Jan-Jun",tblHourly[Weekday],$A7,tblHourly[Hour],I$5) -> 3100.88 | ... Y7: =AVERAGEIFS(tblHourly[Trips],tblHourly[Period],"2015 Jan-Jun",tblHourly[Weekday],$A7,tblHourly[Hour],Y$5) -> 3463.3846
A8: Wed | B8: =AVERAGEIFS(tblHourly[Trips],tblHourly[Period],"2015 Jan-Jun",tblHourly[Weekday],$A8,tblHourly[Hour],B$5) -> 2099.12 | C8: =AVERAGEIFS(tblHourly[Trips],tblHourly[Period],"2015 Jan-Jun",tblHourly[Weekday],$A8,tblHourly[Hour],C$5) -> 1115.32 | D8: =AVERAGEIFS(tblHourly[Trips],tblHourly[Period],"2015 Jan-Jun",tblHourly[Weekday],$A8,tblHourly[Hour],D$5) -> 646.44 | E8: =AVERAGEIFS(tblHourly[Trips],tblHourly[Period],"2015 Jan-Jun",tblHourly[Weekday],$A8,tblHourly[Hour],E$5) -> 441.56 | F8: =AVERAGEIFS(tblHourly[Trips],tblHourly[Period],"2015 Jan-Jun",tblHourly[Weekday],$A8,tblHourly[Hour],F$5) -> 621.72 | G8: =AVERAGEIFS(tblHourly[Trips],tblHourly[Period],"2015 Jan-Jun",tblHourly[Weekday],$A8,tblHourly[Hour],G$5) -> 1018.68 | H8: =AVERAGEIFS(tblHourly[Trips],tblHourly[Period],"2015 Jan-Jun",tblHourly[Weekday],$A8,tblHourly[Hour],H$5) -> 1830.2 | I8: =AVERAGEIFS(tblHourly[Trips],tblHourly[Period],"2015 Jan-Jun",tblHourly[Weekday],$A8,tblHourly[Hour],I$5) -> 3089.56 | ... Y8: =AVERAGEIFS(tblHourly[Trips],tblHourly[Period],"2015 Jan-Jun",tblHourly[Weekday],$A8,tblHourly[Hour],Y$5) -> 3979.6
A9: Thu | B9: =AVERAGEIFS(tblHourly[Trips],tblHourly[Period],"2015 Jan-Jun",tblHourly[Weekday],$A9,tblHourly[Hour],B$5) -> 2550.3846 | C9: =AVERAGEIFS(tblHourly[Trips],tblHourly[Period],"2015 Jan-Jun",tblHourly[Weekday],$A9,tblHourly[Hour],C$5) -> 1455.0769 | D9: =AVERAGEIFS(tblHourly[Trips],tblHourly[Period],"2015 Jan-Jun",tblHourly[Weekday],$A9,tblHourly[Hour],D$5) -> 980.73077 | E9: =AVERAGEIFS(tblHourly[Trips],tblHourly[Period],"2015 Jan-Jun",tblHourly[Weekday],$A9,tblHourly[Hour],E$5) -> 726.03846 | F9: =AVERAGEIFS(tblHourly[Trips],tblHourly[Period],"2015 Jan-Jun",tblHourly[Weekday],$A9,tblHourly[Hour],F$5) -> 804.73077 | G9: =AVERAGEIFS(tblHourly[Trips],tblHourly[Period],"2015 Jan-Jun",tblHourly[Weekday],$A9,tblHourly[Hour],G$5) -> 1130 | H9: =AVERAGEIFS(tblHourly[Trips],tblHourly[Period],"2015 Jan-Jun",tblHourly[Weekday],$A9,tblHourly[Hour],H$5) -> 1878.1538 | I9: =AVERAGEIFS(tblHourly[Trips],tblHourly[Period],"2015 Jan-Jun",tblHourly[Weekday],$A9,tblHourly[Hour],I$5) -> 3094.2692 | ... Y9: =AVERAGEIFS(tblHourly[Trips],tblHourly[Period],"2015 Jan-Jun",tblHourly[Weekday],$A9,tblHourly[Hour],Y$5) -> 5072.6538
A10: Fri | B10: =AVERAGEIFS(tblHourly[Trips],tblHourly[Period],"2015 Jan-Jun",tblHourly[Weekday],$A10,tblHourly[Hour],B$5) -> 3305.3462 | C10: =AVERAGEIFS(tblHourly[Trips],tblHourly[Period],"2015 Jan-Jun",tblHourly[Weekday],$A10,tblHourly[Hour],C$5) -> 1792.9231 | D10: =AVERAGEIFS(tblHourly[Trips],tblHourly[Period],"2015 Jan-Jun",tblHourly[Weekday],$A10,tblHourly[Hour],D$5) -> 1080.8462 | E10: =AVERAGEIFS(tblHourly[Trips],tblHourly[Period],"2015 Jan-Jun",tblHourly[Weekday],$A10,tblHourly[Hour],E$5) -> 750.69231 | F10: =AVERAGEIFS(tblHourly[Trips],tblHourly[Period],"2015 Jan-Jun",tblHourly[Weekday],$A10,tblHourly[Hour],F$5) -> 906.73077 | G10: =AVERAGEIFS(tblHourly[Trips],tblHourly[Period],"2015 Jan-Jun",tblHourly[Weekday],$A10,tblHourly[Hour],G$5) -> 1162.3077 | H10: =AVERAGEIFS(tblHourly[Trips],tblHourly[Period],"2015 Jan-Jun",tblHourly[Weekday],$A10,tblHourly[Hour],H$5) -> 1855.5385 | I10: =AVERAGEIFS(tblHourly[Trips],tblHourly[Period],"2015 Jan-Jun",tblHourly[Weekday],$A10,tblHourly[Hour],I$5) -> 2945.8846 | ... Y10: =AVERAGEIFS(tblHourly[Trips],tblHourly[Period],"2015 Jan-Jun",tblHourly[Weekday],$A10,tblHourly[Hour],Y$5) -> 6462.3077
A11: Sat | B11: =AVERAGEIFS(tblHourly[Trips],tblHourly[Period],"2015 Jan-Jun",tblHourly[Weekday],$A11,tblHourly[Hour],B$5) -> 5608.1154 | C11: =AVERAGEIFS(tblHourly[Trips],tblHourly[Period],"2015 Jan-Jun",tblHourly[Weekday],$A11,tblHourly[Hour],C$5) -> 3988.0385 | D11: =AVERAGEIFS(tblHourly[Trips],tblHourly[Period],"2015 Jan-Jun",tblHourly[Weekday],$A11,tblHourly[Hour],D$5) -> 2767.3077 | E11: =AVERAGEIFS(tblHourly[Trips],tblHourly[Period],"2015 Jan-Jun",tblHourly[Weekday],$A11,tblHourly[Hour],E$5) -> 1918.9615 | F11: =AVERAGEIFS(tblHourly[Trips],tblHourly[Period],"2015 Jan-Jun",tblHourly[Weekday],$A11,tblHourly[Hour],F$5) -> 1430.2308 | G11: =AVERAGEIFS(tblHourly[Trips],tblHourly[Period],"2015 Jan-Jun",tblHourly[Weekday],$A11,tblHourly[Hour],G$5) -> 1017.4615 | H11: =AVERAGEIFS(tblHourly[Trips],tblHourly[Period],"2015 Jan-Jun",tblHourly[Weekday],$A11,tblHourly[Hour],H$5) -> 1045.5769 | I11: =AVERAGEIFS(tblHourly[Trips],tblHourly[Period],"2015 Jan-Jun",tblHourly[Weekday],$A11,tblHourly[Hour],I$5) -> 1228.1538 | ... Y11: =AVERAGEIFS(tblHourly[Trips],tblHourly[Period],"2015 Jan-Jun",tblHourly[Weekday],$A11,tblHourly[Hour],Y$5) -> 6776.1923
A12: Sun | B12: =AVERAGEIFS(tblHourly[Trips],tblHourly[Period],"2015 Jan-Jun",tblHourly[Weekday],$A12,tblHourly[Hour],B$5) -> 6036.5 | C12: =AVERAGEIFS(tblHourly[Trips],tblHourly[Period],"2015 Jan-Jun",tblHourly[Weekday],$A12,tblHourly[Hour],C$5) -> 4829.3846 | D12: =AVERAGEIFS(tblHourly[Trips],tblHourly[Period],"2015 Jan-Jun",tblHourly[Weekday],$A12,tblHourly[Hour],D$5) -> 3500.04 | E12: =AVERAGEIFS(tblHourly[Trips],tblHourly[Period],"2015 Jan-Jun",tblHourly[Weekday],$A12,tblHourly[Hour],E$5) -> 2373.8462 | F12: =AVERAGEIFS(tblHourly[Trips],tblHourly[Period],"2015 Jan-Jun",tblHourly[Weekday],$A12,tblHourly[Hour],F$5) -> 1616.5769 | G12: =AVERAGEIFS(tblHourly[Trips],tblHourly[Period],"2015 Jan-Jun",tblHourly[Weekday],$A12,tblHourly[Hour],G$5) -> 992.07692 | H12: =AVERAGEIFS(tblHourly[Trips],tblHourly[Period],"2015 Jan-Jun",tblHourly[Weekday],$A12,tblHourly[Hour],H$5) -> 895.34615 | I12: =AVERAGEIFS(tblHourly[Trips],tblHourly[Period],"2015 Jan-Jun",tblHourly[Weekday],$A12,tblHourly[Hour],I$5) -> 972.80769 | ... Y12: =AVERAGEIFS(tblHourly[Trips],tblHourly[Period],"2015 Jan-Jun",tblHourly[Weekday],$A12,tblHourly[Hour],Y$5) -> 3044.4231
A15: Hour profile (2015) | L15: Key figures
A16: Hour | B16: Avg trips | E16: Share Mon-Fri | H16: Share Sat-Sun | L16: Peak hour (highest average) | Q16: =INDEX($A$17:$A$40,MATCH(MAX($B$17:$B$40),$B$17:$B$40,0)) -> 19
A17: 0 | B17: =AVERAGEIFS(tblHourly[Trips],tblHourly[Period],"2015 Jan-Jun",tblHourly[Hour],A17) -> 3345.4333 | E17: =SUMIFS(tblHourly[Trips],tblHourly[Period],"2015 Jan-Jun",tblHourly[Hour],A17,tblHourly[Day Type],"Weekday")/SUMIFS(tblHourly[Trips],tblHourly[Period],"2015 Jan-Jun",tblHourly[Day Type],"Weekday") -> 0.030234671 | H17: =SUMIFS(tblHourly[Trips],tblHourly[Period],"2015 Jan-Jun",tblHourly[Hour],A17,tblHourly[Day Type],"Weekend")/SUMIFS(tblHourly[Trips],tblHourly[Period],"2015 Jan-Jun",tblHourly[Day Type],"Weekend") -> 0.069323582 | L17: Quietest hour | Q17: =INDEX($A$17:$A$40,MATCH(MIN($B$17:$B$40),$B$17:$B$40,0)) -> 4
A18: 1 | B18: =AVERAGEIFS(tblHourly[Trips],tblHourly[Period],"2015 Jan-Jun",tblHourly[Hour],A18) -> 2191.7222 | E18: =SUMIFS(tblHourly[Trips],tblHourly[Period],"2015 Jan-Jun",tblHourly[Hour],A18,tblHourly[Day Type],"Weekday")/SUMIFS(tblHourly[Trips],tblHourly[Period],"2015 Jan-Jun",tblHourly[Day Type],"Weekday") -> 0.016687344 | H18: =SUMIFS(tblHourly[Trips],tblHourly[Period],"2015 Jan-Jun",tblHourly[Hour],A18,tblHourly[Day Type],"Weekend")/SUMIFS(tblHourly[Trips],tblHourly[Period],"2015 Jan-Jun",tblHourly[Day Type],"Weekend") -> 0.052492533 | L18: Peak-to-trough ratio | Q18: =MAX($B$17:$B$40)/MIN($B$17:$B$40) -> 5.7900455
A19: 2 | B19: =AVERAGEIFS(tblHourly[Trips],tblHourly[Period],"2015 Jan-Jun",tblHourly[Hour],A19) -> 1455.8827 | E19: =SUMIFS(tblHourly[Trips],tblHourly[Period],"2015 Jan-Jun",tblHourly[Hour],A19,tblHourly[Day Type],"Weekday")/SUMIFS(tblHourly[Trips],tblHourly[Period],"2015 Jan-Jun",tblHourly[Day Type],"Weekday") -> 0.01021414 | H19: =SUMIFS(tblHourly[Trips],tblHourly[Period],"2015 Jan-Jun",tblHourly[Hour],A19,tblHourly[Day Type],"Weekend")/SUMIFS(tblHourly[Trips],tblHourly[Period],"2015 Jan-Jun",tblHourly[Day Type],"Weekend") -> 0.036509825 | L19: Busiest weekday | Q19: =INDEX($L$24:$L$30,MATCH(MAX($O$24:$O$30),$O$24:$O$30,0)) -> Sat
A20: 3 | B20: =AVERAGEIFS(tblHourly[Trips],tblHourly[Period],"2015 Jan-Jun",tblHourly[Hour],A20) -> 1020.3056 | E20: =SUMIFS(tblHourly[Trips],tblHourly[Period],"2015 Jan-Jun",tblHourly[Hour],A20,tblHourly[Day Type],"Weekday")/SUMIFS(tblHourly[Trips],tblHourly[Period],"2015 Jan-Jun",tblHourly[Day Type],"Weekday") -> 0.0072746668 | H20: =SUMIFS(tblHourly[Trips],tblHourly[Period],"2015 Jan-Jun",tblHourly[Hour],A20,tblHourly[Day Type],"Weekend")/SUMIFS(tblHourly[Trips],tblHourly[Period],"2015 Jan-Jun",tblHourly[Day Type],"Weekend") -> 0.025556259 | L20: Quietest weekday | Q20: =INDEX($L$24:$L$30,MATCH(MIN($O$24:$O$30),$O$24:$O$30,0)) -> Mon
A21: 4 | B21: =AVERAGEIFS(tblHourly[Trips],tblHourly[Period],"2015 Jan-Jun",tblHourly[Hour],A21) -> 961.32222 | E21: =SUMIFS(tblHourly[Trips],tblHourly[Period],"2015 Jan-Jun",tblHourly[Hour],A21,tblHourly[Day Type],"Weekday")/SUMIFS(tblHourly[Trips],tblHourly[Period],"2015 Jan-Jun",tblHourly[Day Type],"Weekday") -> 0.0094738696 | H21: =SUMIFS(tblHourly[Trips],tblHourly[Period],"2015 Jan-Jun",tblHourly[Hour],A21,tblHourly[Day Type],"Weekend")/SUMIFS(tblHourly[Trips],tblHourly[Period],"2015 Jan-Jun",tblHourly[Day Type],"Weekend") -> 0.01813848
A22: 5 | B22: =AVERAGEIFS(tblHourly[Trips],tblHourly[Period],"2015 Jan-Jun",tblHourly[Hour],A22) -> 1075.1278 | E22: =SUMIFS(tblHourly[Trips],tblHourly[Period],"2015 Jan-Jun",tblHourly[Hour],A22,tblHourly[Day Type],"Weekday")/SUMIFS(tblHourly[Trips],tblHourly[Period],"2015 Jan-Jun",tblHourly[Day Type],"Weekday") -> 0.014265686 | H22: =SUMIFS(tblHourly[Trips],tblHourly[Period],"2015 Jan-Jun",tblHourly[Hour],A22,tblHourly[Day Type],"Weekend")/SUMIFS(tblHourly[Trips],tblHourly[Period],"2015 Jan-Jun",tblHourly[Day Type],"Weekend") -> 0.011963332 | L22: Average trips per day by weekday (2015)
A23: 6 | B23: =AVERAGEIFS(tblHourly[Trips],tblHourly[Period],"2015 Jan-Jun",tblHourly[Hour],A23) -> 1602.9611 | E23: =SUMIFS(tblHourly[Trips],tblHourly[Period],"2015 Jan-Jun",tblHourly[Hour],A23,tblHourly[Day Type],"Weekday")/SUMIFS(tblHourly[Trips],tblHourly[Period],"2015 Jan-Jun",tblHourly[Day Type],"Weekday") -> 0.024039764 | H23: =SUMIFS(tblHourly[Trips],tblHourly[Period],"2015 Jan-Jun",tblHourly[Hour],A23,tblHourly[Day Type],"Weekend")/SUMIFS(tblHourly[Trips],tblHourly[Period],"2015 Jan-Jun",tblHourly[Day Type],"Weekend") -> 0.011554846 | L23: Weekday | O23: Avg trips per day
A24: 7 | B24: =AVERAGEIFS(tblHourly[Trips],tblHourly[Period],"2015 Jan-Jun",tblHourly[Hour],A24) -> 2464.1278 | E24: =SUMIFS(tblHourly[Trips],tblHourly[Period],"2015 Jan-Jun",tblHourly[Hour],A24,tblHourly[Day Type],"Weekday")/SUMIFS(tblHourly[Trips],tblHourly[Period],"2015 Jan-Jun",tblHourly[Day Type],"Weekday") -> 0.039009671 | H24: =SUMIFS(tblHourly[Trips],tblHourly[Period],"2015 Jan-Jun",tblHourly[Hour],A24,tblHourly[Day Type],"Weekend")/SUMIFS(tblHourly[Trips],tblHourly[Period],"2015 Jan-Jun",tblHourly[Day Type],"Weekend") -> 0.013102926 | L24: Mon | O24: =AVERAGEIFS(tblDaily[Trips],tblDaily[Period],"2015 Jan-Jun",tblDaily[Weekday],L24) -> 65163.538
A25: 8 | B25: =AVERAGEIFS(tblHourly[Trips],tblHourly[Period],"2015 Jan-Jun",tblHourly[Hour],A25) -> 3222.9171 | E25: =SUMIFS(tblHourly[Trips],tblHourly[Period],"2015 Jan-Jun",tblHourly[Hour],A25,tblHourly[Day Type],"Weekday")/SUMIFS(tblHourly[Trips],tblHourly[Period],"2015 Jan-Jun",tblHourly[Day Type],"Weekday") -> 0.050988909 | H25: =SUMIFS(tblHourly[Trips],tblHourly[Period],"2015 Jan-Jun",tblHourly[Hour],A25,tblHourly[Day Type],"Weekend")/SUMIFS(tblHourly[Trips],tblHourly[Period],"2015 Jan-Jun",tblHourly[Day Type],"Weekend") -> 0.017950952 | L25: Tue | O25: =AVERAGEIFS(tblDaily[Trips],tblDaily[Period],"2015 Jan-Jun",tblDaily[Weekday],L25) -> 72034.692
A26: 9 | B26: =AVERAGEIFS(tblHourly[Trips],tblHourly[Period],"2015 Jan-Jun",tblHourly[Hour],A26) -> 3278.6575 | E26: =SUMIFS(tblHourly[Trips],tblHourly[Period],"2015 Jan-Jun",tblHourly[Hour],A26,tblHourly[Day Type],"Weekday")/SUMIFS(tblHourly[Trips],tblHourly[Period],"2015 Jan-Jun",tblHourly[Day Type],"Weekday") -> 0.049063256 | H26: =SUMIFS(tblHourly[Trips],tblHourly[Period],"2015 Jan-Jun",tblHourly[Hour],A26,tblHourly[Day Type],"Weekend")/SUMIFS(tblHourly[Trips],tblHourly[Period],"2015 Jan-Jun",tblHourly[Day Type],"Weekend") -> 0.024627548 | L26: Wed | O26: =AVERAGEIFS(tblDaily[Trips],tblDaily[Period],"2015 Jan-Jun",tblDaily[Weekday],L26) -> 75752.44
A27: 10 | B27: =AVERAGEIFS(tblHourly[Trips],tblHourly[Period],"2015 Jan-Jun",tblHourly[Hour],A27) -> 2873.4365 | E27: =SUMIFS(tblHourly[Trips],tblHourly[Period],"2015 Jan-Jun",tblHourly[Hour],A27,tblHourly[Day Type],"Weekday")/SUMIFS(tblHourly[Trips],tblHourly[Period],"2015 Jan-Jun",tblHourly[Day Type],"Weekday") -> 0.038533458 | H27: =SUMIFS(tblHourly[Trips],tblHourly[Period],"2015 Jan-Jun",tblHourly[Hour],A27,tblHourly[Day Type],"Weekend")/SUMIFS(tblHourly[Trips],tblHourly[Period],"2015 Jan-Jun",tblHourly[Day Type],"Weekend") -> 0.031710341 | L27: Thu | O27: =AVERAGEIFS(tblDaily[Trips],tblDaily[Period],"2015 Jan-Jun",tblDaily[Weekday],L27) -> 83061.462
A28: 11 | B28: =AVERAGEIFS(tblHourly[Trips],tblHourly[Period],"2015 Jan-Jun",tblHourly[Hour],A28) -> 2854.7845 | E28: =SUMIFS(tblHourly[Trips],tblHourly[Period],"2015 Jan-Jun",tblHourly[Hour],A28,tblHourly[Day Type],"Weekday")/SUMIFS(tblHourly[Trips],tblHourly[Period],"2015 Jan-Jun",tblHourly[Day Type],"Weekday") -> 0.035568437 | H28: =SUMIFS(tblHourly[Trips],tblHourly[Period],"2015 Jan-Jun",tblHourly[Hour],A28,tblHourly[Day Type],"Weekend")/SUMIFS(tblHourly[Trips],tblHourly[Period],"2015 Jan-Jun",tblHourly[Day Type],"Weekend") -> 0.037660638 | L28: Fri | O28: =AVERAGEIFS(tblDaily[Trips],tblDaily[Period],"2015 Jan-Jun",tblDaily[Weekday],L28) -> 87791.192
A29: 12 | B29: =AVERAGEIFS(tblHourly[Trips],tblHourly[Period],"2015 Jan-Jun",tblHourly[Hour],A29) -> 2944.8674 | E29: =SUMIFS(tblHourly[Trips],tblHourly[Period],"2015 Jan-Jun",tblHourly[Hour],A29,tblHourly[Day Type],"Weekday")/SUMIFS(tblHourly[Trips],tblHourly[Period],"2015 Jan-Jun",tblHourly[Day Type],"Weekday") -> 0.035513404 | H29: =SUMIFS(tblHourly[Trips],tblHourly[Period],"2015 Jan-Jun",tblHourly[Hour],A29,tblHourly[Day Type],"Weekend")/SUMIFS(tblHourly[Trips],tblHourly[Period],"2015 Jan-Jun",tblHourly[Day Type],"Weekend") -> 0.041518817 | L29: Sat | O29: =AVERAGEIFS(tblDaily[Trips],tblDaily[Period],"2015 Jan-Jun",tblDaily[Weekday],L29) -> 92867.808
A30: 13 | B30: =AVERAGEIFS(tblHourly[Trips],tblHourly[Period],"2015 Jan-Jun",tblHourly[Hour],A30) -> 2971.8729 | E30: =SUMIFS(tblHourly[Trips],tblHourly[Period],"2015 Jan-Jun",tblHourly[Hour],A30,tblHourly[Day Type],"Weekday")/SUMIFS(tblHourly[Trips],tblHourly[Period],"2015 Jan-Jun",tblHourly[Day Type],"Weekday") -> 0.035176844 | H30: =SUMIFS(tblHourly[Trips],tblHourly[Period],"2015 Jan-Jun",tblHourly[Hour],A30,tblHourly[Day Type],"Weekend")/SUMIFS(tblHourly[Trips],tblHourly[Period],"2015 Jan-Jun",tblHourly[Day Type],"Weekend") -> 0.043401197 | L30: Sun | O30: =AVERAGEIFS(tblDaily[Trips],tblDaily[Period],"2015 Jan-Jun",tblDaily[Weekday],L30) -> 75107
A31: 14 | B31: =AVERAGEIFS(tblHourly[Trips],tblHourly[Period],"2015 Jan-Jun",tblHourly[Hour],A31) -> 3229.0773 | E31: =SUMIFS(tblHourly[Trips],tblHourly[Period],"2015 Jan-Jun",tblHourly[Hour],A31,tblHourly[Day Type],"Weekday")/SUMIFS(tblHourly[Trips],tblHourly[Period],"2015 Jan-Jun",tblHourly[Day Type],"Weekday") -> 0.039402981 | H31: =SUMIFS(tblHourly[Trips],tblHourly[Period],"2015 Jan-Jun",tblHourly[Hour],A31,tblHourly[Day Type],"Weekend")/SUMIFS(tblHourly[Trips],tblHourly[Period],"2015 Jan-Jun",tblHourly[Day Type],"Weekend") -> 0.044477823
A32: 15 | B32: =AVERAGEIFS(tblHourly[Trips],tblHourly[Period],"2015 Jan-Jun",tblHourly[Hour],A32) -> 3587.9227 | E32: =SUMIFS(tblHourly[Trips],tblHourly[Period],"2015 Jan-Jun",tblHourly[Hour],A32,tblHourly[Day Type],"Weekday")/SUMIFS(tblHourly[Trips],tblHourly[Period],"2015 Jan-Jun",tblHourly[Day Type],"Weekday") -> 0.044899726 | H32: =SUMIFS(tblHourly[Trips],tblHourly[Period],"2015 Jan-Jun",tblHourly[Hour],A32,tblHourly[Day Type],"Weekend")/SUMIFS(tblHourly[Trips],tblHourly[Period],"2015 Jan-Jun",tblHourly[Day Type],"Weekend") -> 0.046885694 | L32: Share of trips by time band (2015)
A33: 16 | B33: =AVERAGEIFS(tblHourly[Trips],tblHourly[Period],"2015 Jan-Jun",tblHourly[Hour],A33) -> 4072.7624 | E33: =SUMIFS(tblHourly[Trips],tblHourly[Period],"2015 Jan-Jun",tblHourly[Hour],A33,tblHourly[Day Type],"Weekday")/SUMIFS(tblHourly[Trips],tblHourly[Period],"2015 Jan-Jun",tblHourly[Day Type],"Weekday") -> 0.051273264 | H33: =SUMIFS(tblHourly[Trips],tblHourly[Period],"2015 Jan-Jun",tblHourly[Hour],A33,tblHourly[Day Type],"Weekend")/SUMIFS(tblHourly[Trips],tblHourly[Period],"2015 Jan-Jun",tblHourly[Day Type],"Weekend") -> 0.052527107 | L33: Time band | P33: Mon-Fri | R33: Sat-Sun
A34: 17 | B34: =AVERAGEIFS(tblHourly[Trips],tblHourly[Period],"2015 Jan-Jun",tblHourly[Hour],A34) -> 4773.4254 | E34: =SUMIFS(tblHourly[Trips],tblHourly[Period],"2015 Jan-Jun",tblHourly[Hour],A34,tblHourly[Day Type],"Weekday")/SUMIFS(tblHourly[Trips],tblHourly[Period],"2015 Jan-Jun",tblHourly[Day Type],"Weekday") -> 0.061316953 | H34: =SUMIFS(tblHourly[Trips],tblHourly[Period],"2015 Jan-Jun",tblHourly[Hour],A34,tblHourly[Day Type],"Weekend")/SUMIFS(tblHourly[Trips],tblHourly[Period],"2015 Jan-Jun",tblHourly[Day Type],"Weekend") -> 0.058790867 | L34: Night (0-5) | P34: =SUMIFS(tblHourly[Trips],tblHourly[Period],"2015 Jan-Jun",tblHourly[Time Band],L34,tblHourly[Day Type],"Weekday")/SUMIFS(tblHourly[Trips],tblHourly[Period],"2015 Jan-Jun",tblHourly[Day Type],"Weekday") -> 0.088150377 | R34: =SUMIFS(tblHourly[Trips],tblHourly[Period],"2015 Jan-Jun",tblHourly[Time Band],L34,tblHourly[Day Type],"Weekend")/SUMIFS(tblHourly[Trips],tblHourly[Period],"2015 Jan-Jun",tblHourly[Day Type],"Weekend") -> 0.21398401
A35: 18 | B35: =AVERAGEIFS(tblHourly[Trips],tblHourly[Period],"2015 Jan-Jun",tblHourly[Hour],A35) -> 5453.5525 | E35: =SUMIFS(tblHourly[Trips],tblHourly[Period],"2015 Jan-Jun",tblHourly[Hour],A35,tblHourly[Day Type],"Weekday")/SUMIFS(tblHourly[Trips],tblHourly[Period],"2015 Jan-Jun",tblHourly[Day Type],"Weekday") -> 0.072561373 | H35: =SUMIFS(tblHourly[Trips],tblHourly[Period],"2015 Jan-Jun",tblHourly[Hour],A35,tblHourly[Day Type],"Weekend")/SUMIFS(tblHourly[Trips],tblHourly[Period],"2015 Jan-Jun",tblHourly[Day Type],"Weekend") -> 0.061480831 | L35: Morning peak (6-9) | P35: =SUMIFS(tblHourly[Trips],tblHourly[Period],"2015 Jan-Jun",tblHourly[Time Band],L35,tblHourly[Day Type],"Weekday")/SUMIFS(tblHourly[Trips],tblHourly[Period],"2015 Jan-Jun",tblHourly[Day Type],"Weekday") -> 0.1631016 | R35: =SUMIFS(tblHourly[Trips],tblHourly[Period],"2015 Jan-Jun",tblHourly[Time Band],L35,tblHourly[Day Type],"Weekend")/SUMIFS(tblHourly[Trips],tblHourly[Period],"2015 Jan-Jun",tblHourly[Day Type],"Weekend") -> 0.067236273
A36: 19 | B36: =AVERAGEIFS(tblHourly[Trips],tblHourly[Period],"2015 Jan-Jun",tblHourly[Hour],A36) -> 5566.0994 | E36: =SUMIFS(tblHourly[Trips],tblHourly[Period],"2015 Jan-Jun",tblHourly[Hour],A36,tblHourly[Day Type],"Weekday")/SUMIFS(tblHourly[Trips],tblHourly[Period],"2015 Jan-Jun",tblHourly[Day Type],"Weekday") -> 0.073797345 | H36: =SUMIFS(tblHourly[Trips],tblHourly[Period],"2015 Jan-Jun",tblHourly[Hour],A36,tblHourly[Day Type],"Weekend")/SUMIFS(tblHourly[Trips],tblHourly[Period],"2015 Jan-Jun",tblHourly[Day Type],"Weekend") -> 0.063342603 | L36: Midday (10-15) | P36: =SUMIFS(tblHourly[Trips],tblHourly[Period],"2015 Jan-Jun",tblHourly[Time Band],L36,tblHourly[Day Type],"Weekday")/SUMIFS(tblHourly[Trips],tblHourly[Period],"2015 Jan-Jun",tblHourly[Day Type],"Weekday") -> 0.22909485 | R36: =SUMIFS(tblHourly[Trips],tblHourly[Period],"2015 Jan-Jun",tblHourly[Time Band],L36,tblHourly[Day Type],"Weekend")/SUMIFS(tblHourly[Trips],tblHourly[Period],"2015 Jan-Jun",tblHourly[Day Type],"Weekend") -> 0.24565451
A37: 20 | B37: =AVERAGEIFS(tblHourly[Trips],tblHourly[Period],"2015 Jan-Jun",tblHourly[Hour],A37) -> 5240.7403 | E37: =SUMIFS(tblHourly[Trips],tblHourly[Period],"2015 Jan-Jun",tblHourly[Hour],A37,tblHourly[Day Type],"Weekday")/SUMIFS(tblHourly[Trips],tblHourly[Period],"2015 Jan-Jun",tblHourly[Day Type],"Weekday") -> 0.06950628 | H37: =SUMIFS(tblHourly[Trips],tblHourly[Period],"2015 Jan-Jun",tblHourly[Hour],A37,tblHourly[Day Type],"Weekend")/SUMIFS(tblHourly[Trips],tblHourly[Period],"2015 Jan-Jun",tblHourly[Day Type],"Weekend") -> 0.059588606 | L37: Evening peak (16-19) | P37: =SUMIFS(tblHourly[Trips],tblHourly[Period],"2015 Jan-Jun",tblHourly[Time Band],L37,tblHourly[Day Type],"Weekday")/SUMIFS(tblHourly[Trips],tblHourly[Period],"2015 Jan-Jun",tblHourly[Day Type],"Weekday") -> 0.25894893 | R37: =SUMIFS(tblHourly[Trips],tblHourly[Period],"2015 Jan-Jun",tblHourly[Time Band],L37,tblHourly[Day Type],"Weekend")/SUMIFS(tblHourly[Trips],tblHourly[Period],"2015 Jan-Jun",tblHourly[Day Type],"Weekend") -> 0.23614141
A38: 21 | B38: =AVERAGEIFS(tblHourly[Trips],tblHourly[Period],"2015 Jan-Jun",tblHourly[Hour],A38) -> 5140.674 | E38: =SUMIFS(tblHourly[Trips],tblHourly[Period],"2015 Jan-Jun",tblHourly[Hour],A38,tblHourly[Day Type],"Weekday")/SUMIFS(tblHourly[Trips],tblHourly[Period],"2015 Jan-Jun",tblHourly[Day Type],"Weekday") -> 0.068443182 | H38: =SUMIFS(tblHourly[Trips],tblHourly[Period],"2015 Jan-Jun",tblHourly[Hour],A38,tblHourly[Day Type],"Weekend")/SUMIFS(tblHourly[Trips],tblHourly[Period],"2015 Jan-Jun",tblHourly[Day Type],"Weekend") -> 0.057852082 | L38: Late evening (20-23) | P38: =SUMIFS(tblHourly[Trips],tblHourly[Period],"2015 Jan-Jun",tblHourly[Time Band],L38,tblHourly[Day Type],"Weekday")/SUMIFS(tblHourly[Trips],tblHourly[Period],"2015 Jan-Jun",tblHourly[Day Type],"Weekday") -> 0.26070424 | R38: =SUMIFS(tblHourly[Trips],tblHourly[Period],"2015 Jan-Jun",tblHourly[Time Band],L38,tblHourly[Day Type],"Weekend")/SUMIFS(tblHourly[Trips],tblHourly[Period],"2015 Jan-Jun",tblHourly[Day Type],"Weekend") -> 0.2369838
A39: 22 | B39: =AVERAGEIFS(tblHourly[Trips],tblHourly[Period],"2015 Jan-Jun",tblHourly[Hour],A39) -> 5099.1934 | E39: =SUMIFS(tblHourly[Trips],tblHourly[Period],"2015 Jan-Jun",tblHourly[Hour],A39,tblHourly[Day Type],"Weekday")/SUMIFS(tblHourly[Trips],tblHourly[Period],"2015 Jan-Jun",tblHourly[Day Type],"Weekday") -> 0.066262256 | H39: =SUMIFS(tblHourly[Trips],tblHourly[Period],"2015 Jan-Jun",tblHourly[Hour],A39,tblHourly[Day Type],"Weekend")/SUMIFS(tblHourly[Trips],tblHourly[Period],"2015 Jan-Jun",tblHourly[Day Type],"Weekend") -> 0.061078298
A40: 23 | B40: =AVERAGEIFS(tblHourly[Trips],tblHourly[Period],"2015 Jan-Jun",tblHourly[Hour],A40) -> 4526.6056 | E40: =SUMIFS(tblHourly[Trips],tblHourly[Period],"2015 Jan-Jun",tblHourly[Hour],A40,tblHourly[Day Type],"Weekday")/SUMIFS(tblHourly[Trips],tblHourly[Period],"2015 Jan-Jun",tblHourly[Day Type],"Weekday") -> 0.05649252 | H40: =SUMIFS(tblHourly[Trips],tblHourly[Period],"2015 Jan-Jun",tblHourly[Hour],A40,tblHourly[Day Type],"Weekend")/SUMIFS(tblHourly[Trips],tblHourly[Period],"2015 Jan-Jun",tblHourly[Day Type],"Weekend") -> 0.058464811

Sheet Daily_Calendar
A1: Daily view — busiest and quietest days, planning percentiles, holidays and storms
A2: LARGE/SMALL + INDEX/MATCH on the 'Trips 2015' column; PERCENTILE.INC ignores the blank 2014 rows.
A4: Top 10 days of 2015 | F4: Holidays and storm days vs a normal day (same weekday 1-3 weeks before and after, special days excluded)
A5: Rank | B5: Date | C5: Weekday | D5: Trips | F5: Date | G5: Special day | H5: Trips | I5: Normal day | J5: Baseline days | K5: vs normal
A6: 1 | B6: =INDEX(tblDaily[Date],MATCH(D6,tblDaily[Trips 2015],0)) -> 42182 | C6: =CHOOSE(WEEKDAY(B6,2),"Mon","Tue","Wed","Thu","Fri","Sat","Sun") -> Sat | D6: =LARGE(tblDaily[Trips 2015],A6) -> 136193 | F6: =Lookups!H2 -> 41785 | G6: =Lookups!I2 -> Memorial Day | H6: =SUMIFS(tblDaily[Trips],tblDaily[Date],F6) -> 10202 | I6: =(SUMIFS(tblDaily[Trips],tblDaily[Date],F6-21,tblDaily[Special Day],"No")+SUMIFS(tblDaily[Trips],tblDaily[Date],F6-14,tblDaily[Special Day],"No")+SUMIFS(tblDaily[Trips],tblDaily[Date],F6-7,tblDaily[Special Day],"No")+SUMIFS(tblDaily[Trips],tblDaily[Date],F6+7,tblDaily[Special Day],"No")+SUMIFS(tblDaily[Trips],tblDaily[Date],F6+14,tblDaily[Special Day],"No")+SUMIFS(tblDaily[Trips],tblDaily[Date],F6+21,tblDaily[Special Day],"No"))/(COUNTIFS(tblDaily[Date],F6-21,tblDaily[Special Day],"No")+COUNTIFS(tblDaily[Date],F6-14,tblDaily[Special Day],"No")+COUNTIFS(tblDaily[Date],F6-7,tblDaily[Special Day],"No")+COUNTIFS(tblDaily[Date],F6+7,tblDaily[Special Day],"No")+COUNTIFS(tblDaily[Date],F6+14,tblDaily[Special Day],"No")+COUNTIFS(tblDaily[Date],F6+21,tblDaily[Special Day],"No")) -> 18694.833 | J6: =COUNTIFS(tblDaily[Date],F6-21,tblDaily[Special Day],"No")+COUNTIFS(tblDaily[Date],F6-14,tblDaily[Special Day],"No")+COUNTIFS(tblDaily[Date],F6-7,tblDaily[Special Day],"No")+COUNTIFS(tblDaily[Date],F6+7,tblDaily[Special Day],"No")+COUNTIFS(tblDaily[Date],F6+14,tblDaily[Special Day],"No")+COUNTIFS(tblDaily[Date],F6+21,tblDaily[Special Day],"No") -> 6 | K6: =H6/I6-1 -> -0.45428773
A7: 2 | B7: =INDEX(tblDaily[Date],MATCH(D7,tblDaily[Trips 2015],0)) -> 42140 | C7: =CHOOSE(WEEKDAY(B7,2),"Mon","Tue","Wed","Thu","Fri","Sat","Sun") -> Sat | D7: =LARGE(tblDaily[Trips 2015],A7) -> 121557 | F7: =Lookups!H3 -> 41824 | G7: =Lookups!I3 -> Independence Day | H7: =SUMIFS(tblDaily[Trips],tblDaily[Date],F7) -> 14148 | I7: =(SUMIFS(tblDaily[Trips],tblDaily[Date],F7-21,tblDaily[Special Day],"No")+SUMIFS(tblDaily[Trips],tblDaily[Date],F7-14,tblDaily[Special Day],"No")+SUMIFS(tblDaily[Trips],tblDaily[Date],F7-7,tblDaily[Special Day],"No")+SUMIFS(tblDaily[Trips],tblDaily[Date],F7+7,tblDaily[Special Day],"No")+SUMIFS(tblDaily[Trips],tblDaily[Date],F7+14,tblDaily[Special Day],"No")+SUMIFS(tblDaily[Trips],tblDaily[Date],F7+21,tblDaily[Special Day],"No"))/(COUNTIFS(tblDaily[Date],F7-21,tblDaily[Special Day],"No")+COUNTIFS(tblDaily[Date],F7-14,tblDaily[Special Day],"No")+COUNTIFS(tblDaily[Date],F7-7,tblDaily[Special Day],"No")+COUNTIFS(tblDaily[Date],F7+7,tblDaily[Special Day],"No")+COUNTIFS(tblDaily[Date],F7+14,tblDaily[Special Day],"No")+COUNTIFS(tblDaily[Date],F7+21,tblDaily[Special Day],"No")) -> 28160 | J7: =COUNTIFS(tblDaily[Date],F7-21,tblDaily[Special Day],"No")+COUNTIFS(tblDaily[Date],F7-14,tblDaily[Special Day],"No")+COUNTIFS(tblDaily[Date],F7-7,tblDaily[Special Day],"No")+COUNTIFS(tblDaily[Date],F7+7,tblDaily[Special Day],"No")+COUNTIFS(tblDaily[Date],F7+14,tblDaily[Special Day],"No")+COUNTIFS(tblDaily[Date],F7+21,tblDaily[Special Day],"No") -> 6 | K7: =H7/I7-1 -> -0.49758523
A8: 3 | B8: =INDEX(tblDaily[Date],MATCH(D8,tblDaily[Trips 2015],0)) -> 42119 | C8: =CHOOSE(WEEKDAY(B8,2),"Mon","Tue","Wed","Thu","Fri","Sat","Sun") -> Sat | D8: =LARGE(tblDaily[Trips 2015],A8) -> 106270 | F8: =Lookups!H4 -> 41883 | G8: =Lookups!I4 -> Labor Day | H8: =SUMIFS(tblDaily[Trips],tblDaily[Date],F8) -> 19961 | I8: =(SUMIFS(tblDaily[Trips],tblDaily[Date],F8-21,tblDaily[Special Day],"No")+SUMIFS(tblDaily[Trips],tblDaily[Date],F8-14,tblDaily[Special Day],"No")+SUMIFS(tblDaily[Trips],tblDaily[Date],F8-7,tblDaily[Special Day],"No")+SUMIFS(tblDaily[Trips],tblDaily[Date],F8+7,tblDaily[Special Day],"No")+SUMIFS(tblDaily[Trips],tblDaily[Date],F8+14,tblDaily[Special Day],"No")+SUMIFS(tblDaily[Trips],tblDaily[Date],F8+21,tblDaily[Special Day],"No"))/(COUNTIFS(tblDaily[Date],F8-21,tblDaily[Special Day],"No")+COUNTIFS(tblDaily[Date],F8-14,tblDaily[Special Day],"No")+COUNTIFS(tblDaily[Date],F8-7,tblDaily[Special Day],"No")+COUNTIFS(tblDaily[Date],F8+7,tblDaily[Special Day],"No")+COUNTIFS(tblDaily[Date],F8+14,tblDaily[Special Day],"No")+COUNTIFS(tblDaily[Date],F8+21,tblDaily[Special Day],"No")) -> 25801.167 | J8: =COUNTIFS(tblDaily[Date],F8-21,tblDaily[Special Day],"No")+COUNTIFS(tblDaily[Date],F8-14,tblDaily[Special Day],"No")+COUNTIFS(tblDaily[Date],F8-7,tblDaily[Special Day],"No")+COUNTIFS(tblDaily[Date],F8+7,tblDaily[Special Day],"No")+COUNTIFS(tblDaily[Date],F8+14,tblDaily[Special Day],"No")+COUNTIFS(tblDaily[Date],F8+21,tblDaily[Special Day],"No") -> 6 | K8: =H8/I8-1 -> -0.22635281
A9: 4 | B9: =INDEX(tblDaily[Date],MATCH(D9,tblDaily[Trips 2015],0)) -> 42126 | C9: =CHOOSE(WEEKDAY(B9,2),"Mon","Tue","Wed","Thu","Fri","Sat","Sun") -> Sat | D9: =LARGE(tblDaily[Trips 2015],A9) -> 104978 | F9: =Lookups!H5 -> 42005 | G9: =Lookups!I5 -> New Year's Day | H9: =SUMIFS(tblDaily[Trips],tblDaily[Date],F9) -> 58045 | I9: =(SUMIFS(tblDaily[Trips],tblDaily[Date],F9-21,tblDaily[Special Day],"No")+SUMIFS(tblDaily[Trips],tblDaily[Date],F9-14,tblDaily[Special Day],"No")+SUMIFS(tblDaily[Trips],tblDaily[Date],F9-7,tblDaily[Special Day],"No")+SUMIFS(tblDaily[Trips],tblDaily[Date],F9+7,tblDaily[Special Day],"No")+SUMIFS(tblDaily[Trips],tblDaily[Date],F9+14,tblDaily[Special Day],"No")+SUMIFS(tblDaily[Trips],tblDaily[Date],F9+21,tblDaily[Special Day],"No"))/(COUNTIFS(tblDaily[Date],F9-21,tblDaily[Special Day],"No")+COUNTIFS(tblDaily[Date],F9-14,tblDaily[Special Day],"No")+COUNTIFS(tblDaily[Date],F9-7,tblDaily[Special Day],"No")+COUNTIFS(tblDaily[Date],F9+7,tblDaily[Special Day],"No")+COUNTIFS(tblDaily[Date],F9+14,tblDaily[Special Day],"No")+COUNTIFS(tblDaily[Date],F9+21,tblDaily[Special Day],"No")) -> 69348.667 | J9: =COUNTIFS(tblDaily[Date],F9-21,tblDaily[Special Day],"No")+COUNTIFS(tblDaily[Date],F9-14,tblDaily[Special Day],"No")+COUNTIFS(tblDaily[Date],F9-7,tblDaily[Special Day],"No")+COUNTIFS(tblDaily[Date],F9+7,tblDaily[Special Day],"No")+COUNTIFS(tblDaily[Date],F9+14,tblDaily[Special Day],"No")+COUNTIFS(tblDaily[Date],F9+21,tblDaily[Special Day],"No") -> 3 | K9: =H9/I9-1 -> -0.16299761
A10: 5 | B10: =INDEX(tblDaily[Date],MATCH(D10,tblDaily[Trips 2015],0)) -> 42154 | C10: =CHOOSE(WEEKDAY(B10,2),"Mon","Tue","Wed","Thu","Fri","Sat","Sun") -> Sat | D10: =LARGE(tblDaily[Trips 2015],A10) -> 104429 | F10: =Lookups!H6 -> 42023 | G10: =Lookups!I6 -> Birthday of Martin Luther King, Jr. | H10: =SUMIFS(tblDaily[Trips],tblDaily[Date],F10) -> 47025 | I10: =(SUMIFS(tblDaily[Trips],tblDaily[Date],F10-21,tblDaily[Special Day],"No")+SUMIFS(tblDaily[Trips],tblDaily[Date],F10-14,tblDaily[Special Day],"No")+SUMIFS(tblDaily[Trips],tblDaily[Date],F10-7,tblDaily[Special Day],"No")+SUMIFS(tblDaily[Trips],tblDaily[Date],F10+7,tblDaily[Special Day],"No")+SUMIFS(tblDaily[Trips],tblDaily[Date],F10+14,tblDaily[Special Day],"No")+SUMIFS(tblDaily[Trips],tblDaily[Date],F10+21,tblDaily[Special Day],"No"))/(COUNTIFS(tblDaily[Date],F10-21,tblDaily[Special Day],"No")+COUNTIFS(tblDaily[Date],F10-14,tblDaily[Special Day],"No")+COUNTIFS(tblDaily[Date],F10-7,tblDaily[Special Day],"No")+COUNTIFS(tblDaily[Date],F10+7,tblDaily[Special Day],"No")+COUNTIFS(tblDaily[Date],F10+14,tblDaily[Special Day],"No")+COUNTIFS(tblDaily[Date],F10+21,tblDaily[Special Day],"No")) -> 59042 | J10: =COUNTIFS(tblDaily[Date],F10-21,tblDaily[Special Day],"No")+COUNTIFS(tblDaily[Date],F10-14,tblDaily[Special Day],"No")+COUNTIFS(tblDaily[Date],F10-7,tblDaily[Special Day],"No")+COUNTIFS(tblDaily[Date],F10+7,tblDaily[Special Day],"No")+COUNTIFS(tblDaily[Date],F10+14,tblDaily[Special Day],"No")+COUNTIFS(tblDaily[Date],F10+21,tblDaily[Special Day],"No") -> 4 | K10: =H10/I10-1 -> -0.20353308
A11: 6 | B11: =INDEX(tblDaily[Date],MATCH(D11,tblDaily[Trips 2015],0)) -> 42167 | C11: =CHOOSE(WEEKDAY(B11,2),"Mon","Tue","Wed","Thu","Fri","Sat","Sun") -> Fri | D11: =LARGE(tblDaily[Trips 2015],A11) -> 103052 | F11: =Lookups!H7 -> 42051 | G11: =Lookups!I7 -> Washington's Birthday | H11: =SUMIFS(tblDaily[Trips],tblDaily[Date],F11) -> 73672 | I11: =(SUMIFS(tblDaily[Trips],tblDaily[Date],F11-21,tblDaily[Special Day],"No")+SUMIFS(tblDaily[Trips],tblDaily[Date],F11-14,tblDaily[Special Day],"No")+SUMIFS(tblDaily[Trips],tblDaily[Date],F11-7,tblDaily[Special Day],"No")+SUMIFS(tblDaily[Trips],tblDaily[Date],F11+7,tblDaily[Special Day],"No")+SUMIFS(tblDaily[Trips],tblDaily[Date],F11+14,tblDaily[Special Day],"No")+SUMIFS(tblDaily[Trips],tblDaily[Date],F11+21,tblDaily[Special Day],"No"))/(COUNTIFS(tblDaily[Date],F11-21,tblDaily[Special Day],"No")+COUNTIFS(tblDaily[Date],F11-14,tblDaily[Special Day],"No")+COUNTIFS(tblDaily[Date],F11-7,tblDaily[Special Day],"No")+COUNTIFS(tblDaily[Date],F11+7,tblDaily[Special Day],"No")+COUNTIFS(tblDaily[Date],F11+14,tblDaily[Special Day],"No")+COUNTIFS(tblDaily[Date],F11+21,tblDaily[Special Day],"No")) -> 63474.6 | J11: =COUNTIFS(tblDaily[Date],F11-21,tblDaily[Special Day],"No")+COUNTIFS(tblDaily[Date],F11-14,tblDaily[Special Day],"No")+COUNTIFS(tblDaily[Date],F11-7,tblDaily[Special Day],"No")+COUNTIFS(tblDaily[Date],F11+7,tblDaily[Special Day],"No")+COUNTIFS(tblDaily[Date],F11+14,tblDaily[Special Day],"No")+COUNTIFS(tblDaily[Date],F11+21,tblDaily[Special Day],"No") -> 5 | K11: =H11/I11-1 -> 0.16065324
A12: 7 | B12: =INDEX(tblDaily[Date],MATCH(D12,tblDaily[Trips 2015],0)) -> 42055 | C12: =CHOOSE(WEEKDAY(B12,2),"Mon","Tue","Wed","Thu","Fri","Sat","Sun") -> Fri | D12: =LARGE(tblDaily[Trips 2015],A12) -> 102762 | F12: =Lookups!H8 -> 42149 | G12: =Lookups!I8 -> Memorial Day | H12: =SUMIFS(tblDaily[Trips],tblDaily[Date],F12) -> 59748 | I12: =(SUMIFS(tblDaily[Trips],tblDaily[Date],F12-21,tblDaily[Special Day],"No")+SUMIFS(tblDaily[Trips],tblDaily[Date],F12-14,tblDaily[Special Day],"No")+SUMIFS(tblDaily[Trips],tblDaily[Date],F12-7,tblDaily[Special Day],"No")+SUMIFS(tblDaily[Trips],tblDaily[Date],F12+7,tblDaily[Special Day],"No")+SUMIFS(tblDaily[Trips],tblDaily[Date],F12+14,tblDaily[Special Day],"No")+SUMIFS(tblDaily[Trips],tblDaily[Date],F12+21,tblDaily[Special Day],"No"))/(COUNTIFS(tblDaily[Date],F12-21,tblDaily[Special Day],"No")+COUNTIFS(tblDaily[Date],F12-14,tblDaily[Special Day],"No")+COUNTIFS(tblDaily[Date],F12-7,tblDaily[Special Day],"No")+COUNTIFS(tblDaily[Date],F12+7,tblDaily[Special Day],"No")+COUNTIFS(tblDaily[Date],F12+14,tblDaily[Special Day],"No")+COUNTIFS(tblDaily[Date],F12+21,tblDaily[Special Day],"No")) -> 78071 | J12: =COUNTIFS(tblDaily[Date],F12-21,tblDaily[Special Day],"No")+COUNTIFS(tblDaily[Date],F12-14,tblDaily[Special Day],"No")+COUNTIFS(tblDaily[Date],F12-7,tblDaily[Special Day],"No")+COUNTIFS(tblDaily[Date],F12+7,tblDaily[Special Day],"No")+COUNTIFS(tblDaily[Date],F12+14,tblDaily[Special Day],"No")+COUNTIFS(tblDaily[Date],F12+21,tblDaily[Special Day],"No") -> 6 | K12: =H12/I12-1 -> -0.23469662
A13: 8 | B13: =INDEX(tblDaily[Date],MATCH(D13,tblDaily[Trips 2015],0)) -> 42049 | C13: =CHOOSE(WEEKDAY(B13,2),"Mon","Tue","Wed","Thu","Fri","Sat","Sun") -> Sat | D13: =LARGE(tblDaily[Trips 2015],A13) -> 102347 | F13: =Lookups!H9 -> 42030 | G13: =Lookups!I9 -> Blizzard: travel ban from 11 pm (external event) | H13: =SUMIFS(tblDaily[Trips],tblDaily[Date],F13) -> 44310 | I13: =(SUMIFS(tblDaily[Trips],tblDaily[Date],F13-21,tblDaily[Special Day],"No")+SUMIFS(tblDaily[Trips],tblDaily[Date],F13-14,tblDaily[Special Day],"No")+SUMIFS(tblDaily[Trips],tblDaily[Date],F13-7,tblDaily[Special Day],"No")+SUMIFS(tblDaily[Trips],tblDaily[Date],F13+7,tblDaily[Special Day],"No")+SUMIFS(tblDaily[Trips],tblDaily[Date],F13+14,tblDaily[Special Day],"No")+SUMIFS(tblDaily[Trips],tblDaily[Date],F13+21,tblDaily[Special Day],"No"))/(COUNTIFS(tblDaily[Date],F13-21,tblDaily[Special Day],"No")+COUNTIFS(tblDaily[Date],F13-14,tblDaily[Special Day],"No")+COUNTIFS(tblDaily[Date],F13-7,tblDaily[Special Day],"No")+COUNTIFS(tblDaily[Date],F13+7,tblDaily[Special Day],"No")+COUNTIFS(tblDaily[Date],F13+14,tblDaily[Special Day],"No")+COUNTIFS(tblDaily[Date],F13+21,tblDaily[Special Day],"No")) -> 59042 | J13: =COUNTIFS(tblDaily[Date],F13-21,tblDaily[Special Day],"No")+COUNTIFS(tblDaily[Date],F13-14,tblDaily[Special Day],"No")+COUNTIFS(tblDaily[Date],F13-7,tblDaily[Special Day],"No")+COUNTIFS(tblDaily[Date],F13+7,tblDaily[Special Day],"No")+COUNTIFS(tblDaily[Date],F13+14,tblDaily[Special Day],"No")+COUNTIFS(tblDaily[Date],F13+21,tblDaily[Special Day],"No") -> 4 | K13: =H13/I13-1 -> -0.24951729
A14: 9 | B14: =INDEX(tblDaily[Date],MATCH(D14,tblDaily[Trips 2015],0)) -> 42166 | C14: =CHOOSE(WEEKDAY(B14,2),"Mon","Tue","Wed","Thu","Fri","Sat","Sun") -> Thu | D14: =LARGE(tblDaily[Trips 2015],A14) -> 102013 | F14: =Lookups!H10 -> 42031 | G14: =Lookups!I10 -> Blizzard: travel ban until the morning (external event) | H14: =SUMIFS(tblDaily[Trips],tblDaily[Date],F14) -> 25954 | I14: =(SUMIFS(tblDaily[Trips],tblDaily[Date],F14-21,tblDaily[Special Day],"No")+SUMIFS(tblDaily[Trips],tblDaily[Date],F14-14,tblDaily[Special Day],"No")+SUMIFS(tblDaily[Trips],tblDaily[Date],F14-7,tblDaily[Special Day],"No")+SUMIFS(tblDaily[Trips],tblDaily[Date],F14+7,tblDaily[Special Day],"No")+SUMIFS(tblDaily[Trips],tblDaily[Date],F14+14,tblDaily[Special Day],"No")+SUMIFS(tblDaily[Trips],tblDaily[Date],F14+21,tblDaily[Special Day],"No"))/(COUNTIFS(tblDaily[Date],F14-21,tblDaily[Special Day],"No")+COUNTIFS(tblDaily[Date],F14-14,tblDaily[Special Day],"No")+COUNTIFS(tblDaily[Date],F14-7,tblDaily[Special Day],"No")+COUNTIFS(tblDaily[Date],F14+7,tblDaily[Special Day],"No")+COUNTIFS(tblDaily[Date],F14+14,tblDaily[Special Day],"No")+COUNTIFS(tblDaily[Date],F14+21,tblDaily[Special Day],"No")) -> 64353.5 | J14: =COUNTIFS(tblDaily[Date],F14-21,tblDaily[Special Day],"No")+COUNTIFS(tblDaily[Date],F14-14,tblDaily[Special Day],"No")+COUNTIFS(tblDaily[Date],F14-7,tblDaily[Special Day],"No")+COUNTIFS(tblDaily[Date],F14+7,tblDaily[Special Day],"No")+COUNTIFS(tblDaily[Date],F14+14,tblDaily[Special Day],"No")+COUNTIFS(tblDaily[Date],F14+21,tblDaily[Special Day],"No") -> 6 | K14: =H14/I14-1 -> -0.59669637
A15: 10 | B15: =INDEX(tblDaily[Date],MATCH(D15,tblDaily[Trips 2015],0)) -> 42160 | C15: =CHOOSE(WEEKDAY(B15,2),"Mon","Tue","Wed","Thu","Fri","Sat","Sun") -> Fri | D15: =LARGE(tblDaily[Trips 2015],A15) -> 101922
A17: Quietest 5 days of 2015
A18: Rank | B18: Date | C18: Weekday | D18: Trips
A19: 1 | B19: =INDEX(tblDaily[Date],MATCH(D19,tblDaily[Trips 2015],0)) -> 42031 | C19: =CHOOSE(WEEKDAY(B19,2),"Mon","Tue","Wed","Thu","Fri","Sat","Sun") -> Tue | D19: =SMALL(tblDaily[Trips 2015],A19) -> 25954
A20: 2 | B20: =INDEX(tblDaily[Date],MATCH(D20,tblDaily[Trips 2015],0)) -> 42006 | C20: =CHOOSE(WEEKDAY(B20,2),"Mon","Tue","Wed","Thu","Fri","Sat","Sun") -> Fri | D20: =SMALL(tblDaily[Trips 2015],A20) -> 40287
A21: 3 | B21: =INDEX(tblDaily[Date],MATCH(D21,tblDaily[Trips 2015],0)) -> 42008 | C21: =CHOOSE(WEEKDAY(B21,2),"Mon","Tue","Wed","Thu","Fri","Sat","Sun") -> Sun | D21: =SMALL(tblDaily[Trips 2015],A21) -> 41943
A22: 4 | B22: =INDEX(tblDaily[Date],MATCH(D22,tblDaily[Trips 2015],0)) -> 42009 | C22: =CHOOSE(WEEKDAY(B22,2),"Mon","Tue","Wed","Thu","Fri","Sat","Sun") -> Mon | D22: =SMALL(tblDaily[Trips 2015],A22) -> 43678
A23: 5 | B23: =INDEX(tblDaily[Date],MATCH(D23,tblDaily[Trips 2015],0)) -> 42030 | C23: =CHOOSE(WEEKDAY(B23,2),"Mon","Tue","Wed","Thu","Fri","Sat","Sun") -> Mon | D23: =SMALL(tblDaily[Trips 2015],A23) -> 44310
A25: Daily volume to plan for (2015)
A26: 10th percentile | D26: =_xlfn.PERCENTILE.INC(tblDaily[Trips 2015],0.1) -> 59748
A27: Median | D27: =_xlfn.PERCENTILE.INC(tblDaily[Trips 2015],0.5) -> 78343
A28: 90th percentile | D28: =_xlfn.PERCENTILE.INC(tblDaily[Trips 2015],0.9) -> 99756

Sheet Geography
A1: Geography, Jan-Jun 2015 — service areas, zones and airports
A2: Service area = borough, with JFK, LaGuardia and Newark as 'Airports'. Zone names via VLOOKUP on the Lookups sheet. Zone rank = RANK.EQ + COUNTIF tie-break; cumulative share adds zones from the busiest down.
K4: All zones — trips, rank and cumulative share | R4: Top 15 zones
A5: Service area | B5: Trips | C5: Share | D5: Share (known zones) | E5: Trips/day Jan | F5: Trips/day Jun | G5: Growth Jan-Jun | H5: Share Jan | I5: Share Jun | K5: ID | L5: Zone | M5: Borough | N5: Trips | O5: Rank | P5: Cum. share | R5: Rank | S5: Zone | T5: Borough | U5: Trips | V5: Share
A6: Manhattan | B6: =SUMIFS(tblZoneMonthly[Trips],tblZoneMonthly[Service Area],A6) -> 10371060 | C6: =B6/SUM($B$6:$B$12) -> 0.72674926 | D6: =IF(A6="Unknown","",B6/(SUM($B$6:$B$12)-$B$12)) -> 0.7270684 | E6: =SUMIFS(tblZoneMonthly[Trips],tblZoneMonthly[Service Area],A6,tblZoneMonthly[Month],DATE(2015,1,1))/COUNTIFS(tblDaily[Date],">="&DATE(2015,1,1),tblDaily[Date],"<"&EDATE(DATE(2015,1,1),1)) -> 47092.742 | F6: =SUMIFS(tblZoneMonthly[Trips],tblZoneMonthly[Service Area],A6,tblZoneMonthly[Month],DATE(2015,6,1))/COUNTIFS(tblDaily[Date],">="&DATE(2015,6,1),tblDaily[Date],"<"&EDATE(DATE(2015,6,1),1)) -> 66531.267 | G6: =F6/E6-1 -> 0.41277114 | H6: =IF(A6="Unknown","",SUMIFS(tblZoneMonthly[Trips],tblZoneMonthly[Service Area],A6,tblZoneMonthly[Month],DATE(2015,1,1))/(SUMIFS(tblZoneMonthly[Trips],tblZoneMonthly[Month],DATE(2015,1,1))-SUMIFS(tblZoneMonthly[Trips],tblZoneMonthly[Service Area],"Unknown",tblZoneMonthly[Month],DATE(2015,1,1)))) -> 0.74748509 | I6: =IF(A6="Unknown","",SUMIFS(tblZoneMonthly[Trips],tblZoneMonthly[Service Area],A6,tblZoneMonthly[Month],DATE(2015,6,1))/(SUMIFS(tblZoneMonthly[Trips],tblZoneMonthly[Month],DATE(2015,6,1))-SUMIFS(tblZoneMonthly[Trips],tblZoneMonthly[Service Area],"Unknown",tblZoneMonthly[Month],DATE(2015,6,1)))) -> 0.70893107 | K6: 1 | L6: =VLOOKUP(K6,ZoneTable,3,FALSE) -> Newark Airport | M6: =VLOOKUP(K6,ZoneTable,2,FALSE) -> EWR | N6: =SUMIFS(tblZoneMonthly[Trips],tblZoneMonthly[Location ID],K6) -> 105 | O6: =_xlfn.RANK.EQ(N6,$N$6:$N$270,0) -> 252 | P6: =SUMIFS($N$6:$N$270,$O$6:$O$270,"<="&1)/SUM($N$6:$N$270) -> 0.032285672 | R6: 1 | S6: =INDEX($L$6:$L$270,MATCH(R6,$O$6:$O$270,0)) -> Midtown Center | T6: =INDEX($M$6:$M$270,MATCH(R6,$O$6:$O$270,0)) -> Manhattan | U6: =INDEX($N$6:$N$270,MATCH(R6,$O$6:$O$270,0)) -> 460732 | V6: =U6/SUM($N$6:$N$270) -> 0.032285672
A7: Brooklyn | B7: =SUMIFS(tblZoneMonthly[Trips],tblZoneMonthly[Service Area],A7) -> 2322000 | C7: =B7/SUM($B$6:$B$12) -> 0.16271353 | D7: =IF(A7="Unknown","",B7/(SUM($B$6:$B$12)-$B$12)) -> 0.16278498 | E7: =SUMIFS(tblZoneMonthly[Trips],tblZoneMonthly[Service Area],A7,tblZoneMonthly[Month],DATE(2015,1,1))/COUNTIFS(tblDaily[Date],">="&DATE(2015,1,1),tblDaily[Date],"<"&EDATE(DATE(2015,1,1),1)) -> 10007.548 | F7: =SUMIFS(tblZoneMonthly[Trips],tblZoneMonthly[Service Area],A7,tblZoneMonthly[Month],DATE(2015,6,1))/COUNTIFS(tblDaily[Date],">="&DATE(2015,6,1),tblDaily[Date],"<"&EDATE(DATE(2015,6,1),1)) -> 16084.567 | G7: =F7/E7-1 -> 0.60724346 | H7: =IF(A7="Unknown","",SUMIFS(tblZoneMonthly[Trips],tblZoneMonthly[Service Area],A7,tblZoneMonthly[Month],DATE(2015,1,1))/(SUMIFS(tblZoneMonthly[Trips],tblZoneMonthly[Month],DATE(2015,1,1))-SUMIFS(tblZoneMonthly[Trips],tblZoneMonthly[Service Area],"Unknown",tblZoneMonthly[Month],DATE(2015,1,1)))) -> 0.15884599 | I7: =IF(A7="Unknown","",SUMIFS(tblZoneMonthly[Trips],tblZoneMonthly[Service Area],A7,tblZoneMonthly[Month],DATE(2015,6,1))/(SUMIFS(tblZoneMonthly[Trips],tblZoneMonthly[Month],DATE(2015,6,1))-SUMIFS(tblZoneMonthly[Trips],tblZoneMonthly[Service Area],"Unknown",tblZoneMonthly[Month],DATE(2015,6,1)))) -> 0.17139083 | K7: 2 | L7: =VLOOKUP(K7,ZoneTable,3,FALSE) -> Jamaica Bay | M7: =VLOOKUP(K7,ZoneTable,2,FALSE) -> Queens | N7: =SUMIFS(tblZoneMonthly[Trips],tblZoneMonthly[Location ID],K7) -> 8 | O7: =_xlfn.RANK.EQ(N7,$N$6:$N$270,0)+COUNTIF($N$6:N6,N7) -> 260 | P7: =SUMIFS($N$6:$N$270,$O$6:$O$270,"<="&2)/SUM($N$6:$N$270) -> 0.061742006 | R7: 2 | S7: =INDEX($L$6:$L$270,MATCH(R7,$O$6:$O$270,0)) -> TriBeCa/Civic Center | T7: =INDEX($M$6:$M$270,MATCH(R7,$O$6:$O$270,0)) -> Manhattan | U7: =INDEX($N$6:$N$270,MATCH(R7,$O$6:$O$270,0)) -> 420356 | V7: =U7/SUM($N$6:$N$270) -> 0.029456334
A8: Queens | B8: =SUMIFS(tblZoneMonthly[Trips],tblZoneMonthly[Service Area],A8) -> 788657 | C8: =B8/SUM($B$6:$B$12) -> 0.055264928 | D8: =IF(A8="Unknown","",B8/(SUM($B$6:$B$12)-$B$12)) -> 0.055289197 | E8: =SUMIFS(tblZoneMonthly[Trips],tblZoneMonthly[Service Area],A8,tblZoneMonthly[Month],DATE(2015,1,1))/COUNTIFS(tblDaily[Date],">="&DATE(2015,1,1),tblDaily[Date],"<"&EDATE(DATE(2015,1,1),1)) -> 2921.5484 | F8: =SUMIFS(tblZoneMonthly[Trips],tblZoneMonthly[Service Area],A8,tblZoneMonthly[Month],DATE(2015,6,1))/COUNTIFS(tblDaily[Date],">="&DATE(2015,6,1),tblDaily[Date],"<"&EDATE(DATE(2015,6,1),1)) -> 5698.3667 | G8: =F8/E8-1 -> 0.95046116 | H8: =IF(A8="Unknown","",SUMIFS(tblZoneMonthly[Trips],tblZoneMonthly[Service Area],A8,tblZoneMonthly[Month],DATE(2015,1,1))/(SUMIFS(tblZoneMonthly[Trips],tblZoneMonthly[Month],DATE(2015,1,1))-SUMIFS(tblZoneMonthly[Trips],tblZoneMonthly[Service Area],"Unknown",tblZoneMonthly[Month],DATE(2015,1,1)))) -> 0.04637262 | I8: =IF(A8="Unknown","",SUMIFS(tblZoneMonthly[Trips],tblZoneMonthly[Service Area],A8,tblZoneMonthly[Month],DATE(2015,6,1))/(SUMIFS(tblZoneMonthly[Trips],tblZoneMonthly[Month],DATE(2015,6,1))-SUMIFS(tblZoneMonthly[Trips],tblZoneMonthly[Service Area],"Unknown",tblZoneMonthly[Month],DATE(2015,6,1)))) -> 0.060719559 | K8: 3 | L8: =VLOOKUP(K8,ZoneTable,3,FALSE) -> Allerton/Pelham Gardens | M8: =VLOOKUP(K8,ZoneTable,2,FALSE) -> Bronx | N8: =SUMIFS(tblZoneMonthly[Trips],tblZoneMonthly[Location ID],K8) -> 3684 | O8: =_xlfn.RANK.EQ(N8,$N$6:$N$270,0)+COUNTIF($N$6:N7,N8) -> 191 | P8: =SUMIFS($N$6:$N$270,$O$6:$O$270,"<="&3)/SUM($N$6:$N$270) -> 0.091106472 | R8: 3 | S8: =INDEX($L$6:$L$270,MATCH(R8,$O$6:$O$270,0)) -> Union Sq | T8: =INDEX($M$6:$M$270,MATCH(R8,$O$6:$O$270,0)) -> Manhattan | U8: =INDEX($N$6:$N$270,MATCH(R8,$O$6:$O$270,0)) -> 419045 | V8: =U8/SUM($N$6:$N$270) -> 0.029364466
A9: Airports | B9: =SUMIFS(tblZoneMonthly[Trips],tblZoneMonthly[Service Area],A9) -> 555393 | C9: =B9/SUM($B$6:$B$12) -> 0.038919016 | D9: =IF(A9="Unknown","",B9/(SUM($B$6:$B$12)-$B$12)) -> 0.038936107 | E9: =SUMIFS(tblZoneMonthly[Trips],tblZoneMonthly[Service Area],A9,tblZoneMonthly[Month],DATE(2015,1,1))/COUNTIFS(tblDaily[Date],">="&DATE(2015,1,1),tblDaily[Date],"<"&EDATE(DATE(2015,1,1),1)) -> 2225.4516 | F9: =SUMIFS(tblZoneMonthly[Trips],tblZoneMonthly[Service Area],A9,tblZoneMonthly[Month],DATE(2015,6,1))/COUNTIFS(tblDaily[Date],">="&DATE(2015,6,1),tblDaily[Date],"<"&EDATE(DATE(2015,6,1),1)) -> 3843.8667 | G9: =F9/E9-1 -> 0.72722994 | H9: =IF(A9="Unknown","",SUMIFS(tblZoneMonthly[Trips],tblZoneMonthly[Service Area],A9,tblZoneMonthly[Month],DATE(2015,1,1))/(SUMIFS(tblZoneMonthly[Trips],tblZoneMonthly[Month],DATE(2015,1,1))-SUMIFS(tblZoneMonthly[Trips],tblZoneMonthly[Service Area],"Unknown",tblZoneMonthly[Month],DATE(2015,1,1)))) -> 0.035323743 | I9: =IF(A9="Unknown","",SUMIFS(tblZoneMonthly[Trips],tblZoneMonthly[Service Area],A9,tblZoneMonthly[Month],DATE(2015,6,1))/(SUMIFS(tblZoneMonthly[Trips],tblZoneMonthly[Month],DATE(2015,6,1))-SUMIFS(tblZoneMonthly[Trips],tblZoneMonthly[Service Area],"Unknown",tblZoneMonthly[Month],DATE(2015,6,1)))) -> 0.040958735 | K9: 4 | L9: =VLOOKUP(K9,ZoneTable,3,FALSE) -> Alphabet City | M9: =VLOOKUP(K9,ZoneTable,2,FALSE) -> Manhattan | N9: =SUMIFS(tblZoneMonthly[Trips],tblZoneMonthly[Location ID],K9) -> 89319 | O9: =_xlfn.RANK.EQ(N9,$N$6:$N$270,0)+COUNTIF($N$6:N8,N9) -> 52 | P9: =SUMIFS($N$6:$N$270,$O$6:$O$270,"<="&4)/SUM($N$6:$N$270) -> 0.1196683 | R9: 4 | S9: =INDEX($L$6:$L$270,MATCH(R9,$O$6:$O$270,0)) -> East Village | T9: =INDEX($M$6:$M$270,MATCH(R9,$O$6:$O$270,0)) -> Manhattan | U9: =INDEX($N$6:$N$270,MATCH(R9,$O$6:$O$270,0)) -> 407591 | V9: =U9/SUM($N$6:$N$270) -> 0.02856183
